Traceback (most recent call last):
  File "/home/runner/local/lib/python3.11/site-packages/jupyter_cache/executors/utils.py", line 58, in single_nb_execution
    executenb(
  File "/home/runner/local/lib/python3.11/site-packages/nbclient/client.py", line 1314, in execute
    return NotebookClient(nb=nb, resources=resources, km=km, **kwargs).execute()
           ^^^^^^^^^^^^^^^^^^^^^^^^^^^^^^^^^^^^^^^^^^^^^^^^^^^^^^^^^^^^^^^^^^^^^
  File "/home/runner/local/lib/python3.11/site-packages/jupyter_core/utils/__init__.py", line 165, in wrapped
    return loop.run_until_complete(inner)
           ^^^^^^^^^^^^^^^^^^^^^^^^^^^^^^
  File "/home/runner/local/lib/python3.11/asyncio/base_events.py", line 654, in run_until_complete
    return future.result()
           ^^^^^^^^^^^^^^^
  File "/home/runner/local/lib/python3.11/site-packages/nbclient/client.py", line 709, in async_execute
    await self.async_execute_cell(
  File "/home/runner/local/lib/python3.11/site-packages/nbclient/client.py", line 1062, in async_execute_cell
    await self._check_raise_for_error(cell, cell_index, exec_reply)
  File "/home/runner/local/lib/python3.11/site-packages/nbclient/client.py", line 918, in _check_raise_for_error
    raise CellExecutionError.from_cell_and_msg(cell, exec_reply_content)
nbclient.exceptions.CellExecutionError: An error occurred while executing the following cell:
------------------
# Problem data
mu = pk.MU_SUN
max_thrust = 0.12
isp = 3000

# Initial state
ms = 1500.0
rs = np.array([1.2, 0.0, -0.01]) * pk.AU
vs = np.array([0.01, 1, -0.01]) * pk.EARTH_VELOCITY

# Final state
mf = 1300.0
rf = np.array([1, 0.0, -0.0]) * pk.AU
vf = np.array([0.01, 1.1, -0.0]) * pk.EARTH_VELOCITY

# Throttles and tof
nseg = 4
throttles = np.random.uniform(-1, 1, size=(nseg * 3))
tof = 2 * np.pi * np.sqrt(pk.AU**3 / pk.MU_SUN) / 4

udp_nog = pk.trajopt.direct_point2point(
    rvs=[rs, vs],
    rvf=[rf, vf],
    mu=pk.MU_SUN,
    max_thrust=0.22,
    isp=3000,
    tof_bounds=[200, 500],
    mf_bounds=[200.0, 1000.0],
    nseg=nseg,
    cut=0.6,
    with_gradient=False,
)

udp_g = pk.trajopt.direct_point2point(
    rvs=[rs, vs],
    rvf=[rf, vf],
    mu=pk.MU_SUN,
    max_thrust=0.22,
    isp=3000,
    tof_bounds=[200, 500],
    mf_bounds=[200.0, 1000.0],
    nseg=nseg,
    cut=0.6,
    with_gradient=True,
)
------------------


[0;31m---------------------------------------------------------------------------[0m
[0;31mNameError[0m                                 Traceback (most recent call last)
Cell [0;32mIn[3], line 2[0m
[1;32m      1[0m [38;5;66;03m# Problem data[39;00m
[0;32m----> 2[0m mu [38;5;241m=[39m [43mpk[49m[38;5;241m.[39mMU_SUN
[1;32m      3[0m max_thrust [38;5;241m=[39m [38;5;241m0.12[39m
[1;32m      4[0m isp [38;5;241m=[39m [38;5;241m3000[39m

[0;31mNameError[0m: name 'pk' is not defined

